<?xml version="1.0" ?>
<!-- =================================================================================== -->
<!-- |    This document was autogenerated by xacro from soomac.xacro                   | -->
<!-- |    EDITING THIS FILE BY HAND IS NOT RECOMMENDED                                 | -->
<!-- =================================================================================== -->
<robot name="soomac">
  <material name="silver">
    <color rgba="0.700 0.700 0.700 1.000"/>
  </material>
  <transmission name="Component2 to base_link_tran">
    <type>transmission_interface/SimpleTransmission</type>
    <joint name="Component2 to base_link">
      <hardwareInterface>hardware_interface/EffortJointInterface</hardwareInterface>
    </joint>
    <actuator name="Component2 to base_link_actr">
      <hardwareInterface>hardware_interface/EffortJointInterface</hardwareInterface>
      <mechanicalReduction>1</mechanicalReduction>
    </actuator>
  </transmission>
  <transmission name="Component3 to Component2_tran">
    <type>transmission_interface/SimpleTransmission</type>
    <joint name="Component3 to Component2">
      <hardwareInterface>hardware_interface/EffortJointInterface</hardwareInterface>
    </joint>
    <actuator name="Component3 to Component2_actr">
      <hardwareInterface>hardware_interface/EffortJointInterface</hardwareInterface>
      <mechanicalReduction>1</mechanicalReduction>
    </actuator>
  </transmission>
  <transmission name="Component4 to Component3_tran">
    <type>transmission_interface/SimpleTransmission</type>
    <joint name="Component4 to Component3">
      <hardwareInterface>hardware_interface/EffortJointInterface</hardwareInterface>
    </joint>
    <actuator name="Component4 to Component3_actr">
      <hardwareInterface>hardware_interface/EffortJointInterface</hardwareInterface>
      <mechanicalReduction>1</mechanicalReduction>
    </actuator>
  </transmission>
  <transmission name="Component5 to Component4_tran">
    <type>transmission_interface/SimpleTransmission</type>
    <joint name="Component5 to Component4">
      <hardwareInterface>hardware_interface/EffortJointInterface</hardwareInterface>
    </joint>
    <actuator name="Component5 to Component4_actr">
      <hardwareInterface>hardware_interface/EffortJointInterface</hardwareInterface>
      <mechanicalReduction>1</mechanicalReduction>
    </actuator>
  </transmission>
  <transmission name="Component6 to Component5_tran">
    <type>transmission_interface/SimpleTransmission</type>
    <joint name="Component6 to Component5">
      <hardwareInterface>hardware_interface/EffortJointInterface</hardwareInterface>
    </joint>
    <actuator name="Component6 to Component5_actr">
      <hardwareInterface>hardware_interface/EffortJointInterface</hardwareInterface>
      <mechanicalReduction>1</mechanicalReduction>
    </actuator>
  </transmission>
  <gazebo>
    <plugin filename="libgazebo_ros_control.so" name="control"/>
  </gazebo>
  <gazebo reference="base_link">
    <material>Gazebo/Silver</material>
    <mu1>0.2</mu1>
    <mu2>0.2</mu2>
    <selfCollide>true</selfCollide>
    <gravity>true</gravity>
  </gazebo>
  <gazebo reference="Component2_1">
    <material>Gazebo/Silver</material>
    <mu1>0.2</mu1>
    <mu2>0.2</mu2>
    <selfCollide>true</selfCollide>
  </gazebo>
  <gazebo reference="Component3_1">
    <material>Gazebo/Silver</material>
    <mu1>0.2</mu1>
    <mu2>0.2</mu2>
    <selfCollide>true</selfCollide>
  </gazebo>
  <gazebo reference="Component4_1">
    <material>Gazebo/Silver</material>
    <mu1>0.2</mu1>
    <mu2>0.2</mu2>
    <selfCollide>true</selfCollide>
  </gazebo>
  <gazebo reference="Component5_1">
    <material>Gazebo/Silver</material>
    <mu1>0.2</mu1>
    <mu2>0.2</mu2>
    <selfCollide>true</selfCollide>
  </gazebo>
  <gazebo reference="Component6_1">
    <material>Gazebo/Silver</material>
    <mu1>0.2</mu1>
    <mu2>0.2</mu2>
    <selfCollide>true</selfCollide>
  </gazebo>
  <link name="base_link">
    <inertial>
      <origin rpy="0 0 0" xyz="1.3820185154499092e-05 -0.0005045956311069184 0.020522282272331886"/>
      <mass value="1.5026706265949556"/>
      <inertia ixx="0.000984" ixy="0.0" ixz="-0.0" iyy="0.000985" iyz="-1e-06" izz="0.001544"/>
    </inertial>
    <visual>
      <origin rpy="0 0 0" xyz="0 0 0"/>
      <geometry>
        <mesh filename="package://soomac_description/meshes/base_link.stl" scale="0.001 0.001 0.001"/>
      </geometry>
      <material name="silver"/>
    </visual>
    <collision>
      <origin rpy="0 0 0" xyz="0 0 0"/>
      <geometry>
        <mesh filename="package://soomac_description/meshes/base_link.stl" scale="0.001 0.001 0.001"/>
      </geometry>
    </collision>
  </link>
  <link name="Component2_1">
    <inertial>
      <origin rpy="0 0 0" xyz="-0.004855588947938449 -1.5745210662496947e-05 0.0391777283631466"/>
      <mass value="1.718809170564294"/>
      <inertia ixx="0.001233" ixy="-4e-06" ixz="5.4e-05" iyy="0.000991" iyz="-1e-06" izz="0.001466"/>
    </inertial>
    <visual>
      <origin rpy="0 0 0" xyz="-7.4e-05 -0.000224 -0.038032"/>
      <geometry>
        <mesh filename="package://soomac_description/meshes/Component2_1.stl" scale="0.001 0.001 0.001"/>
      </geometry>
      <material name="silver"/>
    </visual>
    <collision>
      <origin rpy="0 0 0" xyz="-7.4e-05 -0.000224 -0.038032"/>
      <geometry>
        <mesh filename="package://soomac_description/meshes/Component2_1.stl" scale="0.001 0.001 0.001"/>
      </geometry>
    </collision>
  </link>
  <link name="Component3_1">
    <inertial>
      <origin rpy="0 0 0" xyz="0.01983497189814815 4.268525940825593e-06 0.17517215930046748"/>
      <mass value="1.0615960702564213"/>
      <inertia ixx="0.015287" ixy="-0.0" ixz="-8.8e-05" iyy="0.015309" iyz="-1e-06" izz="0.00019"/>
    </inertial>
    <visual>
      <origin rpy="0 0 0" xyz="-0.024372 -0.015535 -0.082303"/>
      <geometry>
        <mesh filename="package://soomac_description/meshes/Component3_1.stl" scale="0.001 0.001 0.001"/>
      </geometry>
      <material name="silver"/>
    </visual>
    <collision>
      <origin rpy="0 0 0" xyz="-0.024372 -0.015535 -0.082303"/>
      <geometry>
        <mesh filename="package://soomac_description/meshes/Component3_1.stl" scale="0.001 0.001 0.001"/>
      </geometry>
    </collision>
  </link>
  <link name="Component4_1">
    <inertial>
      <origin rpy="0 0 0" xyz="-0.01983515947046953 0.17517201866259932 4.409159748142155e-06"/>
      <mass value="1.061596070256425"/>
      <inertia ixx="0.015287" ixy="8.8e-05" ixz="0.0" iyy="0.00019" iyz="-1e-06" izz="0.015309"/>
    </inertial>
    <visual>
      <origin rpy="0 0 0" xyz="-0.025872 -0.015535 -0.384053"/>
      <geometry>
        <mesh filename="package://soomac_description/meshes/Component4_1.stl" scale="0.001 0.001 0.001"/>
      </geometry>
      <material name="silver"/>
    </visual>
    <collision>
      <origin rpy="0 0 0" xyz="-0.025872 -0.015535 -0.384053"/>
      <geometry>
        <mesh filename="package://soomac_description/meshes/Component4_1.stl" scale="0.001 0.001 0.001"/>
      </geometry>
    </collision>
  </link>
  <link name="Component5_1">
    <inertial>
      <origin rpy="0 0 0" xyz="0.01952401083921553 0.020355871783710566 -0.007284067763543123"/>
      <mass value="0.549830167921107"/>
      <inertia ixx="0.000269" ixy="-1.1e-05" ixz="4e-06" iyy="0.000137" iyz="5e-05" izz="0.000218"/>
    </inertial>
    <visual>
      <origin rpy="0 0 0" xyz="-0.024372 -0.317285 -0.384053"/>
      <geometry>
        <mesh filename="package://soomac_description/meshes/Component5_1.stl" scale="0.001 0.001 0.001"/>
      </geometry>
      <material name="silver"/>
    </visual>
    <collision>
      <origin rpy="0 0 0" xyz="-0.024372 -0.317285 -0.384053"/>
      <geometry>
        <mesh filename="package://soomac_description/meshes/Component5_1.stl" scale="0.001 0.001 0.001"/>
      </geometry>
    </collision>
  </link>
  <link name="Component6_1">
    <inertial>
      <origin rpy="0 0 0" xyz="-9.378582239288891e-08 0.0019201734593718434 -2.121577674651931e-07"/>
      <mass value="0.00768554963370677"/>
      <inertia ixx="0.0" ixy="0.0" ixz="0.0" iyy="0.0" iyz="-0.0" izz="0.0"/>
    </inertial>
    <visual>
      <origin rpy="0 0 0" xyz="-0.044872 -0.365785 -0.384053"/>
      <geometry>
        <mesh filename="package://soomac_description/meshes/Component6_1.stl" scale="0.001 0.001 0.001"/>
      </geometry>
      <material name="silver"/>
    </visual>
    <collision>
      <origin rpy="0 0 0" xyz="-0.044872 -0.365785 -0.384053"/>
      <geometry>
        <mesh filename="package://soomac_description/meshes/Component6_1.stl" scale="0.001 0.001 0.001"/>
      </geometry>
    </collision>
  </link>
  <joint name="Component2 to base_link" type="continuous">
    <origin rpy="0 0 0" xyz="7.4e-05 0.000224 0.038032"/>
    <parent link="base_link"/>
    <child link="Component2_1"/>
    <axis xyz="0.0 -0.0 1.0"/>
  </joint>
  <joint name="Component3 to Component2" type="continuous">
    <origin rpy="0 0 0" xyz="0.024298 0.015311 0.044271"/>
    <parent link="Component2_1"/>
    <child link="Component3_1"/>
    <axis xyz="1.0 -0.0 -0.0"/>
  </joint>
  <joint name="Component4 to Component3" type="continuous">
    <origin rpy="0 0 0" xyz="0.0015 0.0 0.30175"/>
    <parent link="Component3_1"/>
    <child link="Component4_1"/>
    <axis xyz="-1.0 -0.0 0.0"/>
  </joint>
  <joint name="Component5 to Component4" type="continuous">
    <origin rpy="0 0 0" xyz="-0.0015 0.30175 0.0"/>
    <parent link="Component4_1"/>
    <child link="Component5_1"/>
    <axis xyz="1.0 -0.0 -0.0"/>
  </joint>
  <joint name="Component6 to Component5" type="continuous">
    <origin rpy="0 0 0" xyz="0.0205 0.0485 0.0"/>
    <parent link="Component5_1"/>
    <child link="Component6_1"/>
    <axis xyz="-0.0 1.0 -0.0"/>
  </joint>
</robot>

